[2020-06-16 18:38:21,595] {/home/alta7/.local/lib/python3.6/site-packages/flask/app.py:1892} ERROR - Exception on /publisher/edit [PATCH]
Traceback (most recent call last):
  File "/home/alta7/.local/lib/python3.6/site-packages/sqlalchemy/engine/base.py", line 1284, in _execute_context
    cursor, statement, parameters, context
  File "/home/alta7/.local/lib/python3.6/site-packages/sqlalchemy/engine/default.py", line 590, in do_execute
    cursor.execute(statement, parameters)
  File "/home/alta7/.local/lib/python3.6/site-packages/pymysql/cursors.py", line 170, in execute
    result = self._query(query)
  File "/home/alta7/.local/lib/python3.6/site-packages/pymysql/cursors.py", line 328, in _query
    conn.query(q)
  File "/home/alta7/.local/lib/python3.6/site-packages/pymysql/connections.py", line 517, in query
    self._affected_rows = self._read_query_result(unbuffered=unbuffered)
  File "/home/alta7/.local/lib/python3.6/site-packages/pymysql/connections.py", line 732, in _read_query_result
    result.read()
  File "/home/alta7/.local/lib/python3.6/site-packages/pymysql/connections.py", line 1075, in read
    first_packet = self.connection._read_packet()
  File "/home/alta7/.local/lib/python3.6/site-packages/pymysql/connections.py", line 684, in _read_packet
    packet.check_error()
  File "/home/alta7/.local/lib/python3.6/site-packages/pymysql/protocol.py", line 220, in check_error
    err.raise_mysql_exception(self._data)
  File "/home/alta7/.local/lib/python3.6/site-packages/pymysql/err.py", line 109, in raise_mysql_exception
    raise errorclass(errno, errval)
pymysql.err.IntegrityError: (1062, "Duplicate entry 'Derby's Ads places' for key 'publisher_name'")

The above exception was the direct cause of the following exception:

Traceback (most recent call last):
  File "/home/alta7/.local/lib/python3.6/site-packages/flask/app.py", line 1950, in full_dispatch_request
    rv = self.dispatch_request()
  File "/home/alta7/.local/lib/python3.6/site-packages/flask/app.py", line 1936, in dispatch_request
    return self.view_functions[rule.endpoint](**req.view_args)
  File "/home/alta7/.local/lib/python3.6/site-packages/flask_restful/__init__.py", line 468, in wrapper
    resp = resource(*args, **kwargs)
  File "/home/alta7/.local/lib/python3.6/site-packages/flask/views.py", line 89, in view
    return self.dispatch_request(*args, **kwargs)
  File "/home/alta7/.local/lib/python3.6/site-packages/flask_restful/__init__.py", line 583, in dispatch_request
    resp = meth(*args, **kwargs)
  File "/home/alta7/.local/lib/python3.6/site-packages/flask_jwt_extended/view_decorators.py", line 108, in wrapper
    return fn(*args, **kwargs)
  File "/home/alta7/Documents/project_griffin_backend/blueprints/publisher/resources.py", line 135, in patch
    db.session.commit()
  File "/home/alta7/.local/lib/python3.6/site-packages/sqlalchemy/orm/scoping.py", line 163, in do
    return getattr(self.registry(), name)(*args, **kwargs)
  File "/home/alta7/.local/lib/python3.6/site-packages/sqlalchemy/orm/session.py", line 1042, in commit
    self.transaction.commit()
  File "/home/alta7/.local/lib/python3.6/site-packages/sqlalchemy/orm/session.py", line 504, in commit
    self._prepare_impl()
  File "/home/alta7/.local/lib/python3.6/site-packages/sqlalchemy/orm/session.py", line 483, in _prepare_impl
    self.session.flush()
  File "/home/alta7/.local/lib/python3.6/site-packages/sqlalchemy/orm/session.py", line 2523, in flush
    self._flush(objects)
  File "/home/alta7/.local/lib/python3.6/site-packages/sqlalchemy/orm/session.py", line 2664, in _flush
    transaction.rollback(_capture_exception=True)
  File "/home/alta7/.local/lib/python3.6/site-packages/sqlalchemy/util/langhelpers.py", line 69, in __exit__
    exc_value, with_traceback=exc_tb,
  File "/home/alta7/.local/lib/python3.6/site-packages/sqlalchemy/util/compat.py", line 178, in raise_
    raise exception
  File "/home/alta7/.local/lib/python3.6/site-packages/sqlalchemy/orm/session.py", line 2624, in _flush
    flush_context.execute()
  File "/home/alta7/.local/lib/python3.6/site-packages/sqlalchemy/orm/unitofwork.py", line 422, in execute
    rec.execute(self)
  File "/home/alta7/.local/lib/python3.6/site-packages/sqlalchemy/orm/unitofwork.py", line 589, in execute
    uow,
  File "/home/alta7/.local/lib/python3.6/site-packages/sqlalchemy/orm/persistence.py", line 236, in save_obj
    update,
  File "/home/alta7/.local/lib/python3.6/site-packages/sqlalchemy/orm/persistence.py", line 995, in _emit_update_statements
    statement, multiparams
  File "/home/alta7/.local/lib/python3.6/site-packages/sqlalchemy/engine/base.py", line 1020, in execute
    return meth(self, multiparams, params)
  File "/home/alta7/.local/lib/python3.6/site-packages/sqlalchemy/sql/elements.py", line 298, in _execute_on_connection
    return connection._execute_clauseelement(self, multiparams, params)
  File "/home/alta7/.local/lib/python3.6/site-packages/sqlalchemy/engine/base.py", line 1139, in _execute_clauseelement
    distilled_params,
  File "/home/alta7/.local/lib/python3.6/site-packages/sqlalchemy/engine/base.py", line 1324, in _execute_context
    e, statement, parameters, cursor, context
  File "/home/alta7/.local/lib/python3.6/site-packages/sqlalchemy/engine/base.py", line 1518, in _handle_dbapi_exception
    sqlalchemy_exception, with_traceback=exc_info[2], from_=e
  File "/home/alta7/.local/lib/python3.6/site-packages/sqlalchemy/util/compat.py", line 178, in raise_
    raise exception
  File "/home/alta7/.local/lib/python3.6/site-packages/sqlalchemy/engine/base.py", line 1284, in _execute_context
    cursor, statement, parameters, context
  File "/home/alta7/.local/lib/python3.6/site-packages/sqlalchemy/engine/default.py", line 590, in do_execute
    cursor.execute(statement, parameters)
  File "/home/alta7/.local/lib/python3.6/site-packages/pymysql/cursors.py", line 170, in execute
    result = self._query(query)
  File "/home/alta7/.local/lib/python3.6/site-packages/pymysql/cursors.py", line 328, in _query
    conn.query(q)
  File "/home/alta7/.local/lib/python3.6/site-packages/pymysql/connections.py", line 517, in query
    self._affected_rows = self._read_query_result(unbuffered=unbuffered)
  File "/home/alta7/.local/lib/python3.6/site-packages/pymysql/connections.py", line 732, in _read_query_result
    result.read()
  File "/home/alta7/.local/lib/python3.6/site-packages/pymysql/connections.py", line 1075, in read
    first_packet = self.connection._read_packet()
  File "/home/alta7/.local/lib/python3.6/site-packages/pymysql/connections.py", line 684, in _read_packet
    packet.check_error()
  File "/home/alta7/.local/lib/python3.6/site-packages/pymysql/protocol.py", line 220, in check_error
    err.raise_mysql_exception(self._data)
  File "/home/alta7/.local/lib/python3.6/site-packages/pymysql/err.py", line 109, in raise_mysql_exception
    raise errorclass(errno, errval)
sqlalchemy.exc.IntegrityError: (pymysql.err.IntegrityError) (1062, "Duplicate entry 'Derby's Ads places' for key 'publisher_name'")
[SQL: UPDATE publisher SET publisher_name=%(publisher_name)s, updated_at=%(updated_at)s WHERE publisher.id = %(publisher_id)s]
[parameters: {'publisher_name': "Derby's Ads places", 'updated_at': datetime.datetime(2020, 6, 16, 18, 38, 21, 587126), 'publisher_id': 5}]
(Background on this error at: http://sqlalche.me/e/gkpj)
[2020-06-16 18:38:21,598] {/home/alta7/Documents/project_griffin_backend/blueprints/__init__.py:79} ERROR - REQUEST_LOG	{"method": "PATCH", "code": "500 INTERNAL SERVER ERROR", "uri": "/publisher/edit?", "request": null, "response": {"message": "Internal Server Error"}}
[2020-06-16 18:38:41,597] {/home/alta7/Documents/project_griffin_backend/blueprints/__init__.py:69} WARNING - REQUEST_LOG	{"method": "PATCH", "code": "200 OK", "uri": "/publisher/edit?", "request": null, "response": {"id": 5, "user_id": 5, "publisher_name": "Derby's Ads place", "address": "Jalan Terusan Surabaya,  Malang, Jawa Timur", "publisher_pict": "https://firebasestorage.googleapis.com/v0/b/testapp-22a56.appspot.com/o/images%2Fuser_publisher_pict%2FScreenshot%20from%202020-05-31%2021-01-00.png?alt=media&token=d9ba1240-e2c7-4774-ab31-efa1e25a3774", "company_sertificate": "https://firebasestorage.googleapis.com/v0/b/testapp-22a56.appspot.com/o/images%2Fuser_company_sertificate%2FScreenshot%20from%202020-06-09%2012-32-49.png?alt=media&token=b3a79d66-2afb-4dad-9cc4-b628fa70dca8", "npwp_number": "192112918297526244", "npwp_pict": "https://firebasestorage.googleapis.com/v0/b/testapp-22a56.appspot.com/o/images%2Fuser_npwp_pict%2FScreenshot%20from%202020-05-12%2022-13-15.png?alt=media&token=3caa60e6-add0-4359-a692-71cad9b29ea1", "bank_account_name": "DPS Spot", "bank_account_number": "0112345321", "bank_account_detail": "Bank BRI KCP Surabaya", "is_authorized": false, "created_at": "Tue, 16 Jun 2020 18:37:24 -0000", "updated_at": "Tue, 16 Jun 2020 18:38:42 -0000"}}
