[2020-06-14 20:33:24,813] {/home/alta7/.local/lib/python3.6/site-packages/flask/app.py:1892} ERROR - Exception on /user/profile [POST]
Traceback (most recent call last):
  File "/home/alta7/.local/lib/python3.6/site-packages/sqlalchemy/engine/base.py", line 1284, in _execute_context
    cursor, statement, parameters, context
  File "/home/alta7/.local/lib/python3.6/site-packages/sqlalchemy/engine/default.py", line 590, in do_execute
    cursor.execute(statement, parameters)
  File "/home/alta7/.local/lib/python3.6/site-packages/pymysql/cursors.py", line 170, in execute
    result = self._query(query)
  File "/home/alta7/.local/lib/python3.6/site-packages/pymysql/cursors.py", line 328, in _query
    conn.query(q)
  File "/home/alta7/.local/lib/python3.6/site-packages/pymysql/connections.py", line 517, in query
    self._affected_rows = self._read_query_result(unbuffered=unbuffered)
  File "/home/alta7/.local/lib/python3.6/site-packages/pymysql/connections.py", line 732, in _read_query_result
    result.read()
  File "/home/alta7/.local/lib/python3.6/site-packages/pymysql/connections.py", line 1075, in read
    first_packet = self.connection._read_packet()
  File "/home/alta7/.local/lib/python3.6/site-packages/pymysql/connections.py", line 684, in _read_packet
    packet.check_error()
  File "/home/alta7/.local/lib/python3.6/site-packages/pymysql/protocol.py", line 220, in check_error
    err.raise_mysql_exception(self._data)
  File "/home/alta7/.local/lib/python3.6/site-packages/pymysql/err.py", line 109, in raise_mysql_exception
    raise errorclass(errno, errval)
pymysql.err.IntegrityError: (1062, "Duplicate entry 'admin' for key 'name'")

The above exception was the direct cause of the following exception:

Traceback (most recent call last):
  File "/home/alta7/.local/lib/python3.6/site-packages/flask/app.py", line 1950, in full_dispatch_request
    rv = self.dispatch_request()
  File "/home/alta7/.local/lib/python3.6/site-packages/flask/app.py", line 1936, in dispatch_request
    return self.view_functions[rule.endpoint](**req.view_args)
  File "/home/alta7/.local/lib/python3.6/site-packages/flask_restful/__init__.py", line 468, in wrapper
    resp = resource(*args, **kwargs)
  File "/home/alta7/.local/lib/python3.6/site-packages/flask/views.py", line 89, in view
    return self.dispatch_request(*args, **kwargs)
  File "/home/alta7/.local/lib/python3.6/site-packages/flask_restful/__init__.py", line 583, in dispatch_request
    resp = meth(*args, **kwargs)
  File "/home/alta7/Documents/project_griffin_backend_bu/blueprints/user/resources.py", line 117, in post
    db.session.commit()
  File "/home/alta7/.local/lib/python3.6/site-packages/sqlalchemy/orm/scoping.py", line 163, in do
    return getattr(self.registry(), name)(*args, **kwargs)
  File "/home/alta7/.local/lib/python3.6/site-packages/sqlalchemy/orm/session.py", line 1042, in commit
    self.transaction.commit()
  File "/home/alta7/.local/lib/python3.6/site-packages/sqlalchemy/orm/session.py", line 504, in commit
    self._prepare_impl()
  File "/home/alta7/.local/lib/python3.6/site-packages/sqlalchemy/orm/session.py", line 483, in _prepare_impl
    self.session.flush()
  File "/home/alta7/.local/lib/python3.6/site-packages/sqlalchemy/orm/session.py", line 2523, in flush
    self._flush(objects)
  File "/home/alta7/.local/lib/python3.6/site-packages/sqlalchemy/orm/session.py", line 2664, in _flush
    transaction.rollback(_capture_exception=True)
  File "/home/alta7/.local/lib/python3.6/site-packages/sqlalchemy/util/langhelpers.py", line 69, in __exit__
    exc_value, with_traceback=exc_tb,
  File "/home/alta7/.local/lib/python3.6/site-packages/sqlalchemy/util/compat.py", line 178, in raise_
    raise exception
  File "/home/alta7/.local/lib/python3.6/site-packages/sqlalchemy/orm/session.py", line 2624, in _flush
    flush_context.execute()
  File "/home/alta7/.local/lib/python3.6/site-packages/sqlalchemy/orm/unitofwork.py", line 422, in execute
    rec.execute(self)
  File "/home/alta7/.local/lib/python3.6/site-packages/sqlalchemy/orm/unitofwork.py", line 589, in execute
    uow,
  File "/home/alta7/.local/lib/python3.6/site-packages/sqlalchemy/orm/persistence.py", line 245, in save_obj
    insert,
  File "/home/alta7/.local/lib/python3.6/site-packages/sqlalchemy/orm/persistence.py", line 1136, in _emit_insert_statements
    statement, params
  File "/home/alta7/.local/lib/python3.6/site-packages/sqlalchemy/engine/base.py", line 1020, in execute
    return meth(self, multiparams, params)
  File "/home/alta7/.local/lib/python3.6/site-packages/sqlalchemy/sql/elements.py", line 298, in _execute_on_connection
    return connection._execute_clauseelement(self, multiparams, params)
  File "/home/alta7/.local/lib/python3.6/site-packages/sqlalchemy/engine/base.py", line 1139, in _execute_clauseelement
    distilled_params,
  File "/home/alta7/.local/lib/python3.6/site-packages/sqlalchemy/engine/base.py", line 1324, in _execute_context
    e, statement, parameters, cursor, context
  File "/home/alta7/.local/lib/python3.6/site-packages/sqlalchemy/engine/base.py", line 1518, in _handle_dbapi_exception
    sqlalchemy_exception, with_traceback=exc_info[2], from_=e
  File "/home/alta7/.local/lib/python3.6/site-packages/sqlalchemy/util/compat.py", line 178, in raise_
    raise exception
  File "/home/alta7/.local/lib/python3.6/site-packages/sqlalchemy/engine/base.py", line 1284, in _execute_context
    cursor, statement, parameters, context
  File "/home/alta7/.local/lib/python3.6/site-packages/sqlalchemy/engine/default.py", line 590, in do_execute
    cursor.execute(statement, parameters)
  File "/home/alta7/.local/lib/python3.6/site-packages/pymysql/cursors.py", line 170, in execute
    result = self._query(query)
  File "/home/alta7/.local/lib/python3.6/site-packages/pymysql/cursors.py", line 328, in _query
    conn.query(q)
  File "/home/alta7/.local/lib/python3.6/site-packages/pymysql/connections.py", line 517, in query
    self._affected_rows = self._read_query_result(unbuffered=unbuffered)
  File "/home/alta7/.local/lib/python3.6/site-packages/pymysql/connections.py", line 732, in _read_query_result
    result.read()
  File "/home/alta7/.local/lib/python3.6/site-packages/pymysql/connections.py", line 1075, in read
    first_packet = self.connection._read_packet()
  File "/home/alta7/.local/lib/python3.6/site-packages/pymysql/connections.py", line 684, in _read_packet
    packet.check_error()
  File "/home/alta7/.local/lib/python3.6/site-packages/pymysql/protocol.py", line 220, in check_error
    err.raise_mysql_exception(self._data)
  File "/home/alta7/.local/lib/python3.6/site-packages/pymysql/err.py", line 109, in raise_mysql_exception
    raise errorclass(errno, errval)
sqlalchemy.exc.IntegrityError: (pymysql.err.IntegrityError) (1062, "Duplicate entry 'admin' for key 'name'")
[SQL: INSERT INTO user (name, phone, email, user_type, is_publisher, password, salt, updated_at) VALUES (%(name)s, %(phone)s, %(email)s, %(user_type)s, %(is_publisher)s, %(password)s, %(salt)s, %(updated_at)s)]
[parameters: {'name': 'admin', 'phone': '082326386609', 'email': 'mangkok@gmail.com', 'user_type': 'admin', 'is_publisher': 0, 'password': '13137fdab6e298c8e7a6254b4f40b057a57c5bd76094b8ac6895362ebcf413e603252f77ad519a16877f598aeb571c89c5aec2373bf173aa2d0ffec079a52702', 'salt': 'a1a7f15d312a467fb41e65a30e255d54', 'updated_at': None}]
(Background on this error at: http://sqlalche.me/e/gkpj)
[2020-06-14 20:33:24,825] {/home/alta7/Documents/project_griffin_backend_bu/blueprints/__init__.py:79} ERROR - REQUEST_LOG	{"method": "POST", "code": "500 INTERNAL SERVER ERROR", "uri": "/user/profile?", "request": {"name": "admin", "phone": "082326386609", "email": "mangkok@gmail.com", "user_type": "admin", "password": "admin"}, "response": {"message": "Internal Server Error"}}
[2020-06-14 20:36:02,162] {/home/alta7/Documents/project_griffin_backend_bu/blueprints/__init__.py:69} WARNING - REQUEST_LOG	{"method": "POST", "code": "200 OK", "uri": "/user/profile?", "request": {"name": "Bagas Kurniajati", "phone": "081321324324", "email": "jati@gmail.com", "password": "biasa"}, "response": {"id": 3, "name": "Bagas Kurniajati", "phone": "081321324324", "email": "jati@gmail.com", "user_type": "user", "is_publisher": false, "password": "24fd46f895c6557ca47e76df0bf06bea2b89f4de7c191fc2bc6aec2a8140233a927fe907a6e9287ef09d4c44343215f1c124f8b99f307fe7c5e4f278a258f8ee", "created_at": "Sun, 14 Jun 2020 20:36:02 -0000", "updated_at": null}}
[2020-06-14 20:36:40,609] {/home/alta7/Documents/project_griffin_backend_bu/blueprints/__init__.py:69} WARNING - REQUEST_LOG	{"method": "POST", "code": "200 OK", "uri": "/user/profile?", "request": {"name": "Andre Novado", "phone": "081321324321", "email": "andre@gmail.com", "password": "biasa"}, "response": {"id": 4, "name": "Andre Novado", "phone": "081321324321", "email": "andre@gmail.com", "user_type": "user", "is_publisher": false, "password": "7c0b686d165cda214742ba9f9b17ca40a0711999be45371fff5d39aa4fccc2aebd008626bfe1483eb1e9a5d5d5c70eda3ad2964efa580005295aeb207c9a2f72", "created_at": "Sun, 14 Jun 2020 20:36:40 -0000", "updated_at": null}}
